<robot name="clam_robot">
  <link name="base" />
  <link name="shoulder_pan_link" />
  <link name="shoulder_pitch_link" />
  <link name="elbow_roll_link" />
  <link name="elbow_pitch_link" />
  <link name="wrist_roll_link" />
  <link name="wrist_pitch_link" />
  <link name="gripper_roll_link" />
  <link name="gripper_grip_link" />

  <joint name="shoulder_pan_joint" type="revolute">
    <parent link="base"/>
    <child link="shoulder_pan_link"/>
    <origin xyz="5 3 0" rpy="0 0 0" />
    <axis xyz="-0.9 0.15 0" />
  </joint>

  <joint name="shoulder_pitch_joint" type="revolute">
    <parent link="shoulder_pan_link"/>
    <child link="shoulder_pitch_link"/>
    <origin xyz="-2 5 0" rpy="0 0 1.57" />
    <axis xyz="-0.707 0.707 0" />
  </joint>

  <joint name="elbow_roll_joint" type="revolute">
    <parent link="shoulder_pitch_link"/>
    <child link="elbow_roll_link"/>
    <origin xyz="0 0 0" rpy="0 0 0" />
    <axis xyz="0 0 0" />
  </joint>

  <joint name="elbow_pitch_joint" type="revolute">
    <parent link="elbow_roll_link"/>
    <child link="elbow_pitch_link"/>
    <origin xyz="0 0 0" rpy="0 0 0" />
    <axis xyz="0 0 0" />
  </joint>

  <joint name="wrist_roll_joint" type="revolute">
    <parent link="elbow_pitch_link"/>
    <child link="wrist_roll_link"/>
    <origin xyz="0 0 0" rpy="0 0 0" />
    <axis xyz="0 0 0" />
  </joint>

  <joint name="wrist_pitch_joint" type="revolute">
    <parent link="wrist_roll_link"/>
    <child link="wrist_pitch_link"/>
    <origin xyz="0 0 0" rpy="0 0 0" />
    <axis xyz="0 0 0" />
  </joint>

  <joint name="gripper_roll_joint" type="revolute">
    <parent link="wrist_pitch_link"/>
    <child link="gripper_roll_link"/>
    <origin xyz="0 0 0" rpy="0 0 0" />
    <axis xyz="0 0 0" />
  </joint>

  <joint name="gripper_grip_joint" type="revolute">
    <parent link="gripper_roll_link"/>
    <child link="gripper_grip_link"/>
    <origin xyz="0 0 0" rpy="0 0 0" />
    <axis xyz="0 0 0" />
  </joint>

</robot>