<?xml version="1.0" ?>
<!-- =================================================================================== -->
<!-- |    This document was autogenerated by xacro from clam_urdf.xarco                | -->
<!-- |    EDITING THIS FILE BY HAND IS NOT RECOMMENDED                                 | -->
<!-- =================================================================================== -->
<!-- Robot Description format of CLAM arm 
     Dave Coleman - davetcoleman@gmail.com
     11/6/2011
     
     Documentation:

     URDF
     http://www.ros.org/wiki/urdf/XML

     Joint Safety Limits
     http://www.ros.org/wiki/pr2_controller_manager/safety_limits

     XARCO - Macro Language
     http://www.ros.org/wiki/xacro

-->
<robot name="clam_robot">
  <material name="Black">
    <color rgba="0.0 0.0 0.0 1.0"/>
  </material>
  <material name="Blue">
    <color rgba="0.0 0.0 0.8 1.0"/>
  </material>
  <material name="Green">
    <color rgba="0.0 0.8 0.0 1.0"/>
  </material>
  <material name="Grey">
    <color rgba="0.7 0.7 0.7 1.0"/>
  </material>
  <material name="Grey2">
    <color rgba="0.9 0.9 0.9 1.0"/>
  </material>
  <material name="Red">
    <color rgba="0.8 0.0 0.0 1.0"/>
  </material>
  <material name="White">
    <color rgba="1.0 1.0 1.0 1.0"/>
  </material>
  <material name="GunMetalBrushedAluminum">
    <texture filename="package://smart_arm_description/Media/materials/textures/gun_metal_brushed_aluminum.jpg"/>
  </material>
  <!-- BASE LINK -->
  <link name="base_link">
    <visual>
      <origin rpy="0 0 0" xyz="0 0 0.025"/>
      <geometry>
        <!--mesh filename="package://clam_description/cad/arm_assemblies/stl/base_link.STL"  /-->
        <box size="0.1 0.1 0.05"/>
      </geometry>
      <material name="Black"/>
    </visual>
    <inertial>
      <mass value="25"/>
      <inertia ixx="1.0" ixy="0.0" ixz="0.0" iyy="1.0" iyz="0.0" izz="1.0"/>
    </inertial>
  </link>
  <!-- J0 -->
  <joint name="shoulder_pan_joint" type="revolute">
    <parent link="base_link"/>
    <child link="shoulder_pan_link"/>
    <origin rpy="0 0 0" xyz="0.0 0.0 0.073"/>
    <axis xyz="0 0 1"/>
    <limit effort="300" lower="-2.61799387799" upper="1.98394848567" velocity="1"/>
    <dynamics damping="50" friction="1"/>
  </joint>
  <!-- SHOULDER PAN LINK -->
  <link name="shoulder_pan_link">
    <!--origin xyz="0 0 ${0.086 * .5}" rpy="0 0 0" /-->
    <visual>
      <geometry>
        <cylinder length="0.046" radius="0.03"/>
      </geometry>
      <material name="Red"/>
    </visual>
  </link>
  <!-- J1 -->
  <joint name="shoulder_pitch_joint" type="revolute">
    <parent link="shoulder_pan_link"/>
    <child link="shoulder_pitch_link"/>
    <origin rpy="0 0 0" xyz="0 0.0 0.023"/>
    <axis xyz="0 1 0"/>
    <limit effort="300" lower="-1.19962513147" upper="1.89994105047" velocity="1"/>
    <dynamics damping="50" friction="1"/>
  </joint>
  <!-- SHOULDER PITCH LINK -->
  <link name="shoulder_pitch_link">
    <visual>
      <origin rpy="0 0 0" xyz="0 0 0.0585"/>
      <geometry>
        <cylinder length="0.117" radius="0.02"/>
      </geometry>
      <material name="Grey"/>
    </visual>
  </link>
  <!-- J2 -->
  <joint name="elbow_roll_joint" type="revolute">
    <parent link="shoulder_pitch_link"/>
    <child link="elbow_roll_link"/>
    <origin rpy="0 0 0" xyz="0 0 0.117"/>
    <axis xyz="0 0 1"/>
    <limit effort="300" lower="-2.61799387799" upper="0.705631162427" velocity="1"/>
    <dynamics damping="50" friction="1"/>
  </joint>
  <!-- ELBOW ROLL LINK -->
  <link name="elbow_roll_link">
    <visual>
      <origin rpy="0 0 0" xyz="0 0 0.0195"/>
      <geometry>
        <cylinder length="0.039" radius="0.02"/>
      </geometry>
      <material name="Black"/>
    </visual>
  </link>
  <!-- J3 -->
  <joint name="elbow_pitch_joint" type="revolute">
    <parent link="elbow_roll_link"/>
    <child link="elbow_pitch_link"/>
    <origin rpy="0 0 0" xyz="0 0 0.039"/>
    <axis xyz="0 1 0"/>
    <limit effort="300" lower="-1.5953400194" upper="1.93281579274" velocity="1"/>
    <dynamics damping="50" friction="1"/>
  </joint>
  <link name="elbow_pitch_link">
    <visual>
      <origin rpy="0 0 0" xyz="0 0 0.1075"/>
      <geometry>
        <cylinder length="0.215" radius="0.02"/>
      </geometry>
      <material name="Red"/>
    </visual>
  </link>
  <!-- J4 -->
  <joint name="wrist_roll_joint" type="revolute">
    <parent link="elbow_pitch_link"/>
    <child link="wrist_roll_link"/>
    <origin rpy="0 0 0" xyz="0 0.0 0.215"/>
    <axis xyz="0 0 1"/>
    <limit effort="300" lower="-2.61799387799" upper="2.6128806087" velocity="1"/>
    <dynamics damping="50" friction="1"/>
  </joint>
  <link name="wrist_roll_link">
    <visual>
      <origin rpy="0 0 0" xyz="0 0 0.0165"/>
      <geometry>
        <cylinder length="0.033" radius="0.02"/>
      </geometry>
      <material name="Grey"/>
    </visual>
  </link>
  <!-- J5 -->
  <joint name="wrist_pitch_joint" type="revolute">
    <parent link="wrist_roll_link"/>
    <child link="wrist_pitch_link"/>
    <origin rpy="0 0 0" xyz="0 0 0.033"/>
    <axis xyz="0 1 0"/>
    <limit effort="300" lower="-1.5953400194" upper="1.98394848567" velocity="1"/>
    <dynamics damping="50" friction="1"/>
  </joint>
  <link name="wrist_pitch_link">
    <visual>
      <origin rpy="0 0 0" xyz="0 0 0.0405"/>
      <geometry>
        <cylinder length="0.081" radius="0.02"/>
      </geometry>
      <material name="Black"/>
    </visual>
  </link>
  <!-- J6 -->
  <joint name="gripper_roll_joint" type="revolute">
    <parent link="wrist_pitch_link"/>
    <child link="gripper_roll_link"/>
    <origin rpy="0 0 0" xyz="0 0 0.081"/>
    <axis xyz="0 0 1"/>
    <limit effort="300" lower="-2.61799387799" upper="2.6128806087" velocity="1"/>
    <dynamics damping="50" friction="1"/>
  </joint>
  <link name="gripper_roll_link">
    <visual>
      <origin rpy="0 0 0" xyz="0 0 0.02"/>
      <geometry>
        <cylinder length="0.040" radius="0.025"/>
      </geometry>
      <material name="Red"/>
    </visual>
  </link>
  <!-- J7 -->
  <joint name="gripper_grip_joint" type="revolute">
    <parent link="gripper_roll_link"/>
    <child link="gripper_grip_link"/>
    <origin rpy="0 0 0" xyz="0 0 0.04"/>
    <axis xyz="1 0 0"/>
    <limit effort="300" lower="-0.940841549903" upper="0.0" velocity="1"/>
    <dynamics damping="50" friction="1"/>
  </joint>
  <link name="gripper_grip_link">
    <visual>
      <origin rpy="0 0 0" xyz="0 0 0.03"/>
      <geometry>
        <box size="0.03 0.02 0.060"/>
      </geometry>
      <material name="Grey"/>
    </visual>
  </link>
</robot>

