<?xml version="1.0"?>

<!-- Robot Description format of CLAM arm 
     Dave Coleman - davetcoleman@gmail.com
     11/6/2011
     
     Documentation:

     URDF
     http://www.ros.org/wiki/urdf/XML

     Joint Safety Limits
     http://www.ros.org/wiki/pr2_controller_manager/safety_limits

     XARCO - Macro Language
     http://www.ros.org/wiki/xacro

-->
<robot name="clam_robot">

  <include filename="$(find clam_description)/urdf/materials.urdf.xacro" />

  <!-- BASE LINK -->

  <link name="base_link">
    <visual>
      <origin xyz="0 0 0" rpy="1.5708 0 0" /> <!-- rotate PI/2 -->
      <geometry>
	<mesh filename="package://clam_description/cad/arm_assemblies/stl/base_link.STL" scale=".001 .001 .001" />
	<!--box size="0.1 0.1 0.05" /-->
      </geometry>
      <material name="Grey" />
    </visual>

    <!--collision>
      <origin />
      <geometry />
    </collision-->

    <inertial>
      <mass value="25" />
      <inertia ixx="1.0" ixy ="0.0" ixz="0.0" iyy="1.0" iyz="0.0" izz="1.0" />
    </inertial>
  </link>

  <!-- J0 -->
  <joint name="shoulder_pan_joint" type="revolute">
    <parent link="base_link"/>
    <child link="shoulder_pan_link"/>
    <origin xyz="0 0 0.05" rpy="0 0 0" />
    <axis xyz="0 0 1" />
    <limit effort="300" velocity="1" lower="-2.61799387799" upper="1.98394848567"/>
    <dynamics damping="50" friction="1"/>
  </joint>

  <!-- SHOULDER PAN LINK -->
  <link name="shoulder_pan_link" >
    <visual>
      <origin xyz="0 0 0" rpy="1.5708 0 0" />
      <geometry>
	<mesh filename="package://clam_description/cad/arm_assemblies/stl/shoulder_pan_link.STL" scale=".001 .001 .001" />
	<!--cylinder length="0.046" radius="0.03" /-->
      </geometry>
      <material name="Red" />
    </visual>
  </link>

</robot>