<?xml version="1.0" ?>
<!-- =================================================================================== -->
<!-- |    This document was autogenerated by xacro from clam_urdf.xacro                | -->
<!-- |    EDITING THIS FILE BY HAND IS NOT RECOMMENDED                                 | -->
<!-- =================================================================================== -->
<!-- Robot Description format of CLAM arm 
     Dave Coleman - davetcoleman@gmail.com
     1/10/2012
     
     Documentation:

     URDF
     http://www.ros.org/wiki/urdf/XML

     Joint Safety Limits
     http://www.ros.org/wiki/pr2_controller_manager/safety_limits

     XARCO - Macro Language
     http://www.ros.org/wiki/xacro

-->
<robot name="clam" xmlns:controller="http://playerstage.sourceforge.net/gazebo/xmlschema/#controller" xmlns:interface="http://playerstage.sourceforge.net/gazebo/xmlschema/#interface" xmlns:sensor="http://playerstage.sourceforge.net/gazebo/xmlschema/#sensor">
  <!-- Include materials -->
  <material name="Black">
    <color rgba="0.0 0.0 0.0 1.0"/>
  </material>
  <material name="Blue">
    <color rgba="0.0 0.0 0.8 1.0"/>
  </material>
  <material name="Green">
    <color rgba="0.0 0.8 0.0 1.0"/>
  </material>
  <material name="Grey">
    <color rgba="0.2 0.2 0.2 1.0"/>
  </material>
  <material name="Orange">
    <color rgba="1.0 0.423529411765 0.0392156862745 1.0"/>
  </material>
  <material name="Red">
    <color rgba="0.8 0.0 0.0 1.0"/>
  </material>
  <material name="White">
    <color rgba="1.0 1.0 1.0 1.0"/>
  </material>
  <material name="GunMetalBrushedAluminum">
    <texture filename="package://clam_description/media/gun_metal_brushed_aluminum.jpg"/>
  </material>
  <!-- Constants -->
  <!-- BASE LINK -->
  <link name="base_link">
    <visual>
      <origin rpy="1.570795 0 0" xyz="0 0 0"/>
      <!-- rotate PI/2 -->
      <geometry>
        <mesh filename="package://clam_description/stl/base_link.STL" scale="0.001 0.001 0.001"/>
        <!--box size="0.1 0.1 0.05" /-->
      </geometry>
      <material name="Grey"/>
    </visual>
    <!--collision>
      <origin xyz="0 0 0" rpy="${M_PI/2} 0 0" /> 
      <geometry>
	<mesh filename="package://clam_description/stl/base_link_convex.STL" scale="${M_SCALE} ${M_SCALE} ${M_SCALE}" />
      </geometry>>
    </collision-->
    <inertial>
      <mass value="25"/>
      <inertia ixx="1.0" ixy="0.0" ixz="0.0" iyy="1.0" iyz="0.0" izz="1.0"/>
    </inertial>
  </link>
  <joint name="shoulder_pan_joint" type="revolute">
    <parent link="base_link"/>
    <child link="shoulder_pan_link"/>
    <origin rpy="0 1.570795 0" xyz="0 0 0.05"/>
    <axis xyz="1 0 0"/>
    <limit effort="300" lower="-2.61799387799" upper="1.98394848567" velocity="1"/>
    <dynamics damping="50" friction="1"/>
  </joint>
  <!-- SHOULDER PAN LINK -->
  <link name="shoulder_pan_link">
    <visual>
      <origin rpy="0 0 1.570795" xyz="0 0 0"/>
      <geometry>
        <mesh filename="package://clam_description/stl/shoulder_pan_link.STL" scale="0.001 0.001 0.001"/>
        <!--cylinder length="0.046" radius="0.03" /-->
      </geometry>
      <material name="Orange"/>
    </visual>
  </link>
  <joint name="shoulder_pitch_joint" type="revolute">
    <parent link="shoulder_pan_link"/>
    <child link="shoulder_pitch_link"/>
    <origin rpy="-1.570795 0 1.570795" xyz="0 0 0.0"/>
    <axis xyz="1 0 0"/>
    <limit effort="300" lower="-1.19962513147" upper="1.89994105047" velocity="1"/>
    <dynamics damping="50" friction="1"/>
  </joint>
  <!-- SHOULDER PITCH LINK -->
  <link name="shoulder_pitch_link">
    <visual>
      <origin rpy="1.570795 3.14159 1.570795" xyz="-0.002 0 0.046"/>
      <geometry>
        <mesh filename="package://clam_description/stl/shoulder_pitch_link.STL" scale="0.001 0.001 0.001"/>
        <!--cylinder length="0.117" radius="0.02" /-->
      </geometry>
      <material name="Grey"/>
    </visual>
    <!--collision>
      <origin xyz="-0.002 0 -0.005" rpy="${M_PI/2} ${M_PI} ${M_PI/2}" />
      <geometry>
	<mesh filename="package://clam_description/stl/shoulder_pitch_link_convex.STL" scale="${M_SCALE} ${M_SCALE} ${M_SCALE}" />
      </geometry>
    </collision-->
  </link>
  <joint name="elbow_roll_joint" type="revolute">
    <parent link="shoulder_pitch_link"/>
    <child link="elbow_roll_link"/>
    <origin rpy="0 0 0" xyz="0.004 0 0.152"/>
    <axis xyz="1 0 0"/>
    <limit effort="300" lower="-2.61799387799" upper="0.705631162427" velocity="1"/>
    <dynamics damping="50" friction="1"/>
  </joint>
  <!-- ELBOW ROLL LINK -->
  <link name="elbow_roll_link">
    <visual>
      <origin rpy="1.570795 3.14159 0" xyz="-0.006 0.0 0.0"/>
      <geometry>
        <mesh filename="package://clam_description/stl/elbow_roll_link.STL" scale="0.001 0.001 0.001"/>
        <!--cylinder length="0.039" radius="0.02" /-->
      </geometry>
      <material name="Black"/>
    </visual>
  </link>
  <joint name="elbow_pitch_joint" type="revolute">
    <parent link="elbow_roll_link"/>
    <child link="elbow_pitch_link"/>
    <origin rpy="0 0 0" xyz="0 0 0.0"/>
    <axis xyz="1 0 0"/>
    <limit effort="300" lower="-1.5953400194" upper="1.93281579274" velocity="1"/>
    <dynamics damping="50" friction="1"/>
  </joint>
  <!-- ELBOW PITCH LINK -->
  <link name="elbow_pitch_link">
    <visual>
      <origin rpy="1.570795 3.14159 4.7124" xyz="-0.004 0 0.0"/>
      <geometry>
        <mesh filename="package://clam_description/stl/elbow_pitch_link.STL" scale="0.001 0.001 0.001"/>
        <!--cylinder length="0.215" radius="0.02" /-->
      </geometry>
      <material name="Orange"/>
    </visual>
  </link>
  <joint name="wrist_roll_joint" type="revolute">
    <parent link="elbow_pitch_link"/>
    <child link="wrist_roll_link"/>
    <origin rpy="0 0 0" xyz="-0.004 -0.008 0.248"/>
    <axis xyz="1 0 0"/>
    <limit effort="300" lower="-2.61799387799" upper="2.6128806087" velocity="1"/>
    <dynamics damping="50" friction="1"/>
  </joint>
  <!-- WRIST ROLL LINK -->
  <link name="wrist_roll_link">
    <visual>
      <origin rpy="-1.570795 0 0" xyz="0 0 0"/>
      <geometry>
        <mesh filename="package://clam_description/stl/wrist_roll_link.STL" scale="0.001 0.001 0.001"/>
        <!--cylinder length="0.033" radius="0.02" /-->
      </geometry>
      <material name="Black"/>
    </visual>
  </link>
  <joint name="wrist_pitch_joint" type="revolute">
    <parent link="wrist_roll_link"/>
    <child link="wrist_pitch_link"/>
    <origin rpy="0 0 0" xyz="-00.001 0.000 0"/>
    <axis xyz="1 0 0"/>
    <limit effort="300" lower="-1.5953400194" upper="1.98394848567" velocity="1"/>
    <dynamics damping="50" friction="1"/>
  </joint>
  <!-- WRIST PITCH LINK -->
  <link name="wrist_pitch_link">
    <visual>
      <origin rpy="3.14159 -1.570795 0" xyz="0 0 0"/>
      <geometry>
        <mesh filename="package://clam_description/stl/wrist_pitch_link.STL" scale="0.001 0.001 0.001"/>
        <!--cylinder length="0.081" radius="0.02" /-->
      </geometry>
      <material name="Grey"/>
    </visual>
  </link>
  <joint name="gripper_roll_joint" type="revolute">
    <parent link="wrist_pitch_link"/>
    <child link="gripper_roll_link"/>
    <origin rpy="0 0 0" xyz="0 0 0.081"/>
    <axis xyz="1 0 0"/>
    <limit effort="300" lower="-2.61799387799" upper="2.6128806087" velocity="1"/>
    <dynamics damping="50" friction="1"/>
  </joint>
  <!-- GRIPPER ROLL LINK -->
  <link name="gripper_roll_link">
    <visual>
      <origin rpy="0 0 0" xyz="0 0 0.02"/>
      <geometry>
        <cylinder length="0.040" radius="0.025"/>
      </geometry>
      <material name="Orange"/>
    </visual>
  </link>
  <joint name="gripper_grip_joint" type="revolute">
    <parent link="gripper_roll_link"/>
    <child link="gripper_grip_link"/>
    <origin rpy="0 0 0" xyz="0 0 0.04"/>
    <axis xyz="1 0 0"/>
    <limit effort="300" lower="-0.940841549903" upper="0.0" velocity="1"/>
    <dynamics damping="50" friction="1"/>
  </joint>
  <!-- GRIPPER GRIP LINK -->
  <link name="gripper_grip_link">
    <visual>
      <origin rpy="0 0 0" xyz="0 0 0.03"/>
      <geometry>
        <box size="0.03 0.02 0.060"/>
      </geometry>
      <material name="Black"/>
    </visual>
  </link>
</robot>

